time: 2017-10-30 17:39:05.352020Z
tags: worker-2
test: tacker.tests.unit.nfvo.drivers.vim.test_kubernetes_driver.TestKubernetes_Driver.test_deregister_vim
time: 2017-10-30 17:39:05.367794Z
successful: tacker.tests.unit.nfvo.drivers.vim.test_kubernetes_driver.TestKubernetes_Driver.test_deregister_vim [ multipart
]
tags: -worker-2
time: 2017-10-30 17:39:05.463285Z
tags: worker-0
test: tacker.tests.unit.nfvo.drivers.vim.test_kubernetes_driver.TestKubernetes_Driver.test_deregister_vim_barbican
time: 2017-10-30 17:39:05.500556Z
successful: tacker.tests.unit.nfvo.drivers.vim.test_kubernetes_driver.TestKubernetes_Driver.test_deregister_vim_barbican [ multipart
]
tags: -worker-0
time: 2017-10-30 17:39:05.667926Z
tags: worker-3
test: tacker.tests.unit.nfvo.drivers.vim.test_kubernetes_driver.TestKubernetes_Driver.test_encode_vim_auth_barbican
time: 2017-10-30 17:39:05.681849Z
successful: tacker.tests.unit.nfvo.drivers.vim.test_kubernetes_driver.TestKubernetes_Driver.test_encode_vim_auth_barbican [ multipart
]
tags: -worker-3
time: 2017-10-30 17:39:05.672637Z
tags: worker-1
test: tacker.tests.unit.nfvo.drivers.vim.test_kubernetes_driver.TestKubernetes_Driver.test_register_k8sclient
time: 2017-10-30 17:39:05.691242Z
failure: tacker.tests.unit.nfvo.drivers.vim.test_kubernetes_driver.TestKubernetes_Driver.test_register_k8sclient [ multipart
Content-Type: text/x-traceback;charset=utf8,language=python
traceback
3F2
Traceback (most recent call last):
  File "tacker/tests/unit/nfvo/drivers/vim/test_kubernetes_driver.py", line 92, in test_register_k8sclient
    self.kubernetes_api.initialize_CoreApiClient.assert_called_once_with(auth_obj)
  File "/opt/stack/tacker/.tox/py27/local/lib/python2.7/site-packages/mock/mock.py", line 948, in assert_called_once_with
    return self.assert_called_with(*args, **kwargs)
  File "/opt/stack/tacker/.tox/py27/local/lib/python2.7/site-packages/mock/mock.py", line 937, in assert_called_with
    six.raise_from(AssertionError(_error_message(cause)), cause)
  File "/opt/stack/tacker/.tox/py27/local/lib/python2.7/site-packages/six.py", line 737, in raise_from
    raise value
AssertionError: Expected call: initialize_CoreApiClient({'ssl_ca_cert': None, 'auth_url': 'https://localhost:6443', 'password': 'test_password', 'username': 'test_user'})
Actual call: initialize_CoreApiClient(auth_url='https://localhost:6443', password='test_password', ssl_ca_cert=None, username='test_user')
0
]
tags: -worker-1
